Workbook
Name Abgeschlossenheitsbescheinigung: INPUT_Stammdaten!$C$22
Name Abzahl_TG: INPUT_Stammdaten!$C$40
Name Adresse: INPUT_Stammdaten!$C$10
Name Anzahl_Stellplätze: INPUT_Stammdaten!$C$39
Name anzvollgeschosse: #REF!
Name Aufgeteilt_nach_WEG: INPUT_Stammdaten!$C$23
Name Baujahr: INPUT_Stammdaten!$C$14
Name Bezirk: INPUT_Stammdaten!$C$12
Name Bodenrichtwert: INPUT_Stammdaten!$C$17
Name Dachgeschoß_Ausbau: INPUT_Stammdaten!$C$21
Name Darlehen_Bank: INPUT_Finanzierung!$C$7
Name Darlehen_Mezzanin: INPUT_Finanzierung!#REF!
Name Einheiten_Gewerbe: INPUT_Stammdaten!$C$35
Name EK_Notwendig: INPUT_Finanzierung!$C$18
Name EK_Verzinsung: INPUT_Finanzierung!#REF!
Name Gebäudeteile: INPUT_Stammdaten!$C$19
Name Gesamt_Vermietbare_Fläche: INPUT_Stammdaten!$C$42
Name Gesamtinvestitionskosten: INPUT_Stammdaten!$C$51
Name Gesamtkosten_Sanierung: #REF!
Name gewerbeeinheiten: #REF!
Name GIK: #REF!
Name GoogleMaps_Link: INPUT_Stammdaten!$C$11
Name grundstücksgröße: #REF!
Name Kapitalbindung_Bank: INPUT_Finanzierung!$C$14
Name Kapitalbindung_Mezzanin: INPUT_Finanzierung!#REF!
Name Kaufpreis: INPUT_Stammdaten!$C$45
Name KNK: INPUT_Stammdaten!$C$47
Name kosten_Mietereinigung: #REF!
Name kosten_sanierung: #REF!
Name Kosten_WEG_Aufteilung: INPUT_Stammdaten!$C$48
Name Leerstand_Gewerbe: INPUT_Stammdaten!$C$37
Name Leerstand_Wohnen: INPUT_Stammdaten!$C$34
Name Letzte_Sanierung: INPUT_Stammdaten!$C$15
Name Maklerkosten: INPUT_Stammdaten!$C$46
Name Nettokaltmiete: 'INPUT_Verkaufseinschätzung Mark'!#REF!
Name Objekttyp: INPUT_Stammdaten!$C$13
Name Potential_Nachverdichtung: INPUT_Stammdaten!#REF!
Name Sanierungskosten_Einheiten: #REF!
Name Sanierungskosten_Gemeinschaftseigentum: #REF!
Name Sonstige_vermietbare_Fläche: INPUT_Stammdaten!$C$38
Name stand: #REF!
Name Strukturierungsentgelt_Bank: INPUT_Finanzierung!$C$9
Name Tilgung_Bank: INPUT_Finanzierung!$C$10
Name Tilgung_Mezzanin: INPUT_Finanzierung!#REF!
Name Tilgungsfreie_Zeit_Bank: INPUT_Finanzierung!$C$12
Name verkaufserlös_Soll: #REF!
Name Verkaufserlöse_BaseCase: 'INPUT_Verkaufseinschätzung Mark'!$H$24
Name Verkaufserlöse_BestCase: 'INPUT_Verkaufseinschätzung Mark'!#REF!
Name Verkaufserlöse_WorstCase: 'INPUT_Verkaufseinschätzung Mark'!#REF!
Name Vermietbare_Fläche_Soll: INPUT_Stammdaten!#REF!
Name Wert_Boden: INPUT_Stammdaten!$C$18
Name WFL_Wohnen: INPUT_Stammdaten!$C$33
Name wohneinheiten: #REF!
Name Zins_Bank: INPUT_Finanzierung!$C$11
Name Zins_Mezzanin: INPUT_Finanzierung!#REF!
Name Zinskosten_Bank: INPUT_Finanzierung!$C$15
Name Zinskosten_Mezzanin: INPUT_Finanzierung!#REF!
Name Zinskoten_gesamt: INPUT_Finanzierung!$C$19
Name Anzahl_Wohneinheiten: INPUT_Stammdaten!$C$32
Name anzvollgeschosse: INPUT_Stammdaten!$C$20

Sheet Business Case (intern)
B2: Annahmen Feld
B4: Business Case
D5: Stand | E5: 06.10.2025
B6: Verkaufserlöse
C7: Base Case | D7: Best Case | E7: Worst Case
B8: Abgabepreis/ qm | C8: ='INPUT_Verkaufseinschätzung Mark'!G24 | D8: ='INPUT_Verkaufseinschätzung Mark'!#REF! | E8: ='INPUT_Verkaufseinschätzung Mark'!#REF!
B10: Verkaufserlös ingesamt | C10: =Verkaufserlöse_BaseCase | D10: =Verkaufserlöse_BestCase | E10: =Verkaufserlöse_WorstCase
B11: Gesamt Einnahmen | C11: =SUM(C10:C10) | D11: =SUM(D10:D10) | E11: =SUM(E10:E10)
B13: =INPUT_Stammdaten!B45 | C13: =INPUT_Stammdaten!$C$45 | D13: =INPUT_Stammdaten!$C$45 | E13: =INPUT_Stammdaten!$C$45
B14: =INPUT_Stammdaten!B46 | C14: =INPUT_Stammdaten!$C$46 | D14: =INPUT_Stammdaten!$C$46 | E14: =INPUT_Stammdaten!$C$46
B15: =INPUT_Stammdaten!B47 | C15: =INPUT_Stammdaten!$C$47 | D15: =INPUT_Stammdaten!$C$47 | E15: =INPUT_Stammdaten!$C$47
B16: =INPUT_Stammdaten!B48 | C16: =INPUT_Stammdaten!$C$48 | D16: =INPUT_Stammdaten!$C$48 | E16: =INPUT_Stammdaten!$C$48
B17: =INPUT_Stammdaten!B49 | C17: =INPUT_Stammdaten!$C$49 | D17: =INPUT_Stammdaten!$C$49 | E17: =INPUT_Stammdaten!$C$49
B18: =INPUT_Stammdaten!B50 | C18: =INPUT_Stammdaten!$C$50 | D18: =INPUT_Stammdaten!$C$50 | E18: =INPUT_Stammdaten!$C$50
B19: Finanzierungskosten Bank | C19: =Zinskosten_Bank | D19: =Zinskosten_Bank | E19: =Zinskosten_Bank
B20: Gesamtkosten (inkl. Finanzierungskosten) | C20: =SUM(C13:C19) | D20: =SUM(D13:D19) | E20: =SUM(E13:E19)
B23: Projektgewinn (vor Steuern) | C23: =C11-C20 | D23: =D11-D20 | E23: =E11-E20
B24: Marge ( in %) | C24: =C23/C20 | D24: =D23/D20 | E24: =E23/E20

Sheet INPUT_Stammdaten
B2: Annahmen Feld
B4: INPUT - Stammdaten
D5: Stand | E5: 26.03.2026
B6: Projekt Zusammenfassung
B9: Facts
B10: Adresse | C10: Oranienburger Straße 6 in 16321 Bernau
B11: Google Maps Link | C11: https://maps.google.com/?q=Oranienburger+Straße+6+in+16321+Bernau
B12: Bezirk / Ortteil | C12: Rehberge
B13: Objekttyp | C13: Mehrfamilienhaus mit Stellplätzen und Neubaupotenzial
B14: Baujahr | C14: 1920
B15: letzte wesentliche Modernisierung | C15: 2000
B16: Gründstücksgröße (in qm) WEG | C16: 1172
B17: Bodenrichtwert (je qm)
B18: Wert Grund & Boden | C18: =grundstücksgröße*Bodenrichtwert
B19: Gebäudeteile
B20: Anzahl Vollgeschosse (ohne EG & DG) | C20: 0
B21: DG ausgebaut? | C21: Ja
B22: Abgeschlossenheitsbescheinigung:
B23: Aufgeteilt nach WEG
B24: Sperrfrist für Eigenbedarf
B25: Verdichtungspotential?
B26: Sanierungsgebiet?
B27: Milieuschutzgebiet?
B28: Ensenbleschutz / Denkmal?
B29: Objekt Fotos
B31: Flächen
B32: Einheiten - Wohnen | C32: 11
B33: WFL - Wohnen (in qm) | C33: 594.54
B34: Leerstand Wohnen (in qm) | C34: 0
B35: Einheiten - Gewerbe
B36: WFL - Gewerbe (in qm)
B37: Leerstand Gewerbe (in qm)
B38: Sonstige vermietbare Fläche (in qm)
B39: Anzahl Stellplätze
B40: Anzahl Tiefgaragenstellplätze
B41: Anzahl Garagen
B42: Gesamt vermietbare Fläche Bestand (in qm) | C42: =C38+C36+C33 | E42: =SUM(E32:E37)
B44: Erwerbskosten
B45: Kaufpreis | C45: 1350000
B46: Makler | C46: =C45*D46 | D46: 0.0714
...

Sheet INPUT_Verkaufseinschätzung Mark
B3: Verkaufseinschätzung | G3: Profit (Base Case) | H3: ='Business Case (intern)'!C23
G6: Price Source: Manual Input
G7: Base Case
B8: Objekt Nummer | C8: Typ | D8: Etage | E8: Raum laut Grundriss | F8: Fläche / WFL SOLL (qm) | G8: I. Base Case Verkaufspreis je qm | H8: I. Base Case Verkaufspreis je Objekt
B9: 1 | C9: WE | D9: EG li | E9: 46.95 | F9: =$F$24/INPUT_Stammdaten!Anzahl_Wohneinheiten | G9: 3200 | H9: =G9*F9
B10: 2 | C10: WE | D10: EG mi | E10: 52.49 | F10: =$F$24/INPUT_Stammdaten!Anzahl_Wohneinheiten | G10: 3200 | H10: =G10*F10
B11: 3 | C11: WE | D11: EG re | E11: 49.16 | F11: =$F$24/INPUT_Stammdaten!Anzahl_Wohneinheiten | G11: 3200 | H11: =G11*F11
B12: 4 | C12: WE | D12: 1. OG li | E12: 50 | F12: =$F$24/INPUT_Stammdaten!Anzahl_Wohneinheiten | G12: 3200 | H12: =G12*F12
B13: 5 | C13: WE | D13: 1. OG mi | E13: 51.18 | F13: =$F$24/INPUT_Stammdaten!Anzahl_Wohneinheiten | G13: 3200 | H13: =G13*F13
B14: 6 | C14: WE | D14: 1. OG re | E14: 50.47 | F14: =$F$24/INPUT_Stammdaten!Anzahl_Wohneinheiten | G14: 3200 | H14: =G14*F14
B15: 7 | C15: WE | D15: 2. OG li | E15: 50.61 | F15: =$F$24/INPUT_Stammdaten!Anzahl_Wohneinheiten | G15: 3200 | H15: =G15*F15
B16: 8 | C16: WE | D16: 2. OG mi | E16: 51.39 | F16: =$F$24/INPUT_Stammdaten!Anzahl_Wohneinheiten | G16: 3200 | H16: =G16*F16
B17: 9 | C17: WE | D17: 2. OG re | E17: 50.21 | F17: =$F$24/INPUT_Stammdaten!Anzahl_Wohneinheiten | G17: 3200 | H17: =G17*F17
B18: 10 | C18: WE | D18: DG li | E18: 80.52 | F18: =$F$24/INPUT_Stammdaten!Anzahl_Wohneinheiten | G18: 3200 | H18: =G18*F18
B19: 11 | C19: WE | D19: DG re | E19: 61.56 | F19: =$F$24/INPUT_Stammdaten!Anzahl_Wohneinheiten | G19: 3200 | H19: =G19*F19
E24: Gesamt | F24: 594.54 | G24: =H24/$F$24 | H24: =SUM(H9:H23)

Sheet INPUT_Finanzierung
B2: Annahmen Feld
B3: INPUT - Finanzierung
D4: Stand | E4: 07.07.2025
B6: Bankendarlehen (FK)
B7: Darlehen Bank (FK) | C7: =Kaufpreis
B8: Leverage (% vom Kaufpreis) (LTV) | C8: =C7/Kaufpreis
B9: Strukturierungsentgelt | C9: 0
B10: Tilgung p.a. | C10: 0.01
B11: Zins p.a. | C11: 0.04
B12: Tilgungsfreie Zeit (in Monaten) | C12: 0
B14: Kapitalbindung Bankendarlehen (in Jahren) | C14: 1.5
B15: Zinskosten Bank über Projektdauer | C15: =C9*C7+C7*C11*C14
B17: Eigenkapital (EK)
B18: Notwendiges EK | C18: =Gesamtinvestitionskosten-C7
B19: Gesamt Zinskosten | C19: =C15
C20: Monthly Rent | D20: 0
C21: Annual Rent | D21: 0
C22: Price per sqm | D22: 3200
C23: Estimated Price | D23: 1902528
C24: Gross Yield (%) | D24: 0
